<?xml version="1.0"?>
<robot xmlns:xacro="http://www.ros.org/wiki/xacro" >

    <xacro:include filename="inertial_macros.xacro"/>

    <material name="white">
        <color rgba="1 1 1 1" />
    </material>

    <material name="orange">
        <color rgba="1 0.3 0.1 1"/>
    </material>

    <material name="blue">
        <color rgba="0.2 0.2 1 1"/>
    </material>

    <material name="black">
        <color rgba="0 0 0 1"/>
    </material>

    <material name="red">
        <color rgba="1 0 0 1"/>
    </material>

    <!-- BASE LINK -->

    <link name="base_link">

    </link>
    
    <!-- BASE_FOOTPRINT LINK -->

    <joint name="base_footprint_joint" type="fixed">
        <parent link="base_link"/>
        <child link="base_footprint"/>
        <origin xyz="0 0 0" rpy="0 0 0"/>
    </joint>

    <link name="base_footprint">
    </link>

    <!-- CHASSIS LINK -->

    <joint name="chassis_joint" type="fixed">
        <parent link="base_link"/>
        <child link="chassis"/>
        <origin xyz="-0.1 0 0"/>
    </joint>

    <link name="chassis">
        <visual>
            <origin xyz="0.15 0 0.075"/>
            <geometry>
                <box size="0.3 0.3 0.15"/>
            </geometry>
            <material name="white"/>
        </visual>
        <collision>
            <origin xyz="0.15 0 0.075"/>
            <geometry>
                <box size="0.3 0.3 0.15"/>
            </geometry>
        </collision>
        <xacro:inertial_box mass="2.0" x="0.3" y="0.3" z="0.15">
            <origin xyz="0.15 0 0.075" rpy="0 0 0"/>
        </xacro:inertial_box>
    </link>

    <gazebo reference="chassis">
        <material>Gazebo/White</material>
    </gazebo>

    <!-- LEFT WHEEL LINK -->

    <joint name="left_wheel_joint" type="continuous">
        <parent link="base_link"/>
        <child link="left_wheel"/>
        <origin xyz="0 0.175 0" rpy="-${pi/2} 0 0" />
        <axis xyz="0 0 1"/>
    </joint>

    <link name="left_wheel">
        <visual>
            <geometry>
                <cylinder radius="0.05" length="0.04"/>
            </geometry>
            <material name="blue"/>
        </visual>
        <collision>
            <geometry>
                <cylinder radius="0.05" length="0.04"/>
            </geometry>
        </collision>
        <xacro:inertial_cylinder mass="2.0" length="0.04" radius="0.05">
            <origin xyz="0 0 0" rpy="0 0 0"/>
        </xacro:inertial_cylinder>
    </link>

    <gazebo reference="left_wheel">
        <material>Gazebo/Blue</material>
    </gazebo>

    <!-- RIGHT WHEEL LINK -->

    <joint name="right_wheel_joint" type="continuous">
        <parent link="base_link"/>
        <child link="right_wheel"/>
        <origin xyz="0 -0.175 0" rpy="${pi/2} 0 0" />
        <axis xyz="0 0 -1"/>
    </joint>

    <link name="right_wheel">
        <visual>
            <geometry>
                <cylinder radius="0.05" length="0.04"/>
            </geometry>
            <material name="blue"/>
        </visual>
        <collision>
            <geometry>
                <cylinder radius="0.05" length="0.04"/>
            </geometry>
        </collision>
        <xacro:inertial_cylinder mass="2.0" length="0.04" radius="0.05">
            <origin xyz="0 0 0" rpy="0 0 0"/>
        </xacro:inertial_cylinder>
    </link>

    <gazebo reference="right_wheel">
        <material>Gazebo/Blue</material>
    </gazebo>

    <joint name="gripper_axis_joint" type="fixed">
        <parent link="laser_frame"/>
        <child link="gripper_axis"/>
        <origin xyz="0 0 -0.0175"/>
    </joint>

    <link name='gripper_axis'>
      <visual>
          <geometry>
              <cylinder radius="0.004" length="0.035"/>
          </geometry>
          <material name="blue"/>
      </visual>
      <collision>
            <geometry>
                <cylinder radius="0.004" length="0.035"/>
            </geometry>
        </collision>
        <xacro:inertial_cylinder mass="0.0001" length="0.004" radius="0.035">
            <origin xyz="0 0 0" rpy="0 0 0"/>
        </xacro:inertial_cylinder>
    </link>

    <joint name="gripper_R_joint" type="revolute">
        <parent link="gripper_axis"/>
        <child link="gripper_R"/>
        <origin xyz="0 0 -0.0175"/>
        <limit lower="-1.57" upper="0.0" effort="-1" velocity="-1" />
        <axis xyz="0 0 1"/>
    </joint>

    <link name='gripper_R'>
      <visual>
        <geometry>
          <mesh filename="file://$(find articubot_one)/description/model/gripR_lab.dae" scale="1 1 1"/>
        </geometry>
        <material name="blue"/>
      </visual>
      <collision>
        <geometry>
          <mesh filename="file://$(find articubot_one)/description/model/gripR_lab.dae" scale="1 1 1"/>
        </geometry>
      </collision>
      <xacro:grip mass="0.1">
          <origin xyz="0 0 0" rpy="0 0 0"/>
      </xacro:grip>
    </link>

    <gazebo reference="gripper_R">
        <material>Gazebo/White</material>
        <static>true</static>
    </gazebo>

    <joint name="gripper_L_joint" type="revolute">
        <parent link="gripper_axis"/>
        <child link="gripper_L"/>
        <origin xyz="0 0 -0.0175"/>
        <limit lower="-1.57" upper="0.0" effort="-1" velocity="-1" />
        <axis xyz="0 0 -1"/>
    </joint>

    <link name='gripper_L'>
      <visual>
        <geometry>
          <mesh filename="file://$(find articubot_one)/description/model/gripL_lab.dae" scale="1 1 1"/>
        </geometry>
        <material name="blue"/>
      </visual>
      <collision>
        <geometry>
          <mesh filename="file://$(find articubot_one)/description/model/gripL_lab.dae" scale="1 1 1"/>
        </geometry>
      </collision>
      <xacro:grip mass="0.1">
          <origin xyz="0 0 0" rpy="0 0 0"/>
      </xacro:grip>
    </link>

    <gazebo reference="gripper_L">
        <material>Gazebo/White</material>
        <static>true</static>
    </gazebo>

    <!-- CASTER WHEEL LINK -->

    <joint name="caster_wheel_joint" type="fixed">
        <parent link="laser_frame"/>
        <child link="caster_wheel"/>
        <limit effort="1000.0" lower="0.0" upper="0.548" velocity="0.5"/>
        <origin xyz="0 0 -0.035"/>
    </joint>

    <link name="caster_wheel">
        <visual>
            <geometry>
                <sphere radius="0.005"/>
            </geometry>
            <material name="black"/>
        </visual>
        <collision>
            <geometry>
                <sphere radius="0.005"/>
            </geometry>
        </collision>
        <xacro:inertial_sphere mass="1.0" radius="0.005">
            <origin xyz="0 0 0" rpy="0 0 0"/>
        </xacro:inertial_sphere>
    </link>

    <gazebo reference="caster_wheel">
        <material>Gazebo/Black</material>
        <mu1 value="0.001"/>
        <mu2 value="0.001"/>
    </gazebo>

</robot>
